"""エラー回復シナリオ統合テスト."""

import pytest
import platform
import tempfile
import shutil
import time
from pathlib import Path
from unittest.mock import Mock, patch, MagicMock
from ..multiplatform.helpers import verify_current_platform


class TestErrorRecoveryScenarios:
    """エラー回復シナリオ統合テストクラス."""

    def setup_method(self):
        """テストメソッドの前処理."""
        self.platform_info = verify_current_platform()
        self.temp_dir = Path(tempfile.mkdtemp())

    def teardown_method(self):
        """テストメソッドの後処理."""
        if self.temp_dir.exists():
            shutil.rmtree(self.temp_dir)

    @pytest.mark.integration
    def test_file_operation_error_recovery(self):
        """ファイル操作エラーの回復シナリオテスト."""
        # ファイル操作回復機能
        class FileOperationRecovery:
            def __init__(self, max_retries=3, retry_delay=0.1):
                self.max_retries = max_retries
                self.retry_delay = retry_delay
            
            def safe_file_operation(self, operation, *args, **kwargs):
                last_error = None
                
                for attempt in range(self.max_retries + 1):
                    try:
                        return operation(*args, **kwargs)
                    except (OSError, IOError, PermissionError) as e:
                        last_error = e
                        if attempt < self.max_retries:
                            time.sleep(self.retry_delay * (2 ** attempt))  # Exponential backoff
                            continue
                        else:
                            raise last_error
                
                raise last_error
        
        # テスト用ファイル操作
        def write_test_file(file_path, content):
            with open(file_path, 'w') as f:
                f.write(content)
            return True
        
        # 回復機能テスト
        recovery = FileOperationRecovery(max_retries=2, retry_delay=0.01)
        test_file = self.temp_dir / "recovery_test.txt"
        
        # 正常なファイル操作
        result = recovery.safe_file_operation(write_test_file, test_file, "test content")
        assert result is True
        assert test_file.exists()
        assert test_file.read_text() == "test content"

    @pytest.mark.integration
    def test_network_error_recovery(self):
        """ネットワークエラーの回復シナリオテスト."""
        # ネットワーク回復機能
        class NetworkRecovery:
            def __init__(self, max_retries=3, timeout=5):
                self.max_retries = max_retries
                self.timeout = timeout
                self.attempt_count = 0
            
            def resilient_request(self, url, simulate_failure=False):
                self.attempt_count += 1
                
                # 失敗シミュレーション
                if simulate_failure and self.attempt_count <= 2:
                    if self.attempt_count == 1:
                        raise ConnectionError("Connection timeout")
                    elif self.attempt_count == 2:
                        raise ConnectionError("Connection refused")
                
                # 成功レスポンス
                return {
                    'status_code': 200,
                    'content': 'Success',
                    'attempts': self.attempt_count
                }
            
            def request_with_retry(self, url):
                last_error = None
                
                for attempt in range(self.max_retries + 1):
                    try:
                        return self.resilient_request(url, simulate_failure=True)
                    except ConnectionError as e:
                        last_error = e
                        if attempt < self.max_retries:
                            time.sleep(0.01 * (2 ** attempt))  # Exponential backoff
                            continue
                        else:
                            raise last_error
                
                raise last_error
        
        # ネットワーク回復テスト
        network = NetworkRecovery(max_retries=3)
        
        # 回復成功シナリオ
        response = network.request_with_retry("http://example.com")
        assert response['status_code'] == 200
        assert response['attempts'] == 3  # 2回失敗後、3回目で成功

    @pytest.mark.integration
    def test_dependency_resolution_error_recovery(self):
        """依存関係解決エラーの回復シナリオテスト."""
        # 依存関係回復機能
        class DependencyRecovery:
            def __init__(self):
                self.fallback_sources = [
                    'primary_source',
                    'mirror_source',
                    'local_cache'
                ]
                self.resolved_packages = set()
            
            def resolve_dependency(self, package_name, source):
                # ソース別の成功/失敗シミュレーション
                if source == 'primary_source' and package_name == 'failing_package':
                    raise ConnectionError("Primary source unavailable")
                elif source == 'mirror_source' and package_name == 'failing_package':
                    raise ConnectionError("Mirror source timeout")
                elif source == 'local_cache':
                    # ローカルキャッシュは常に成功（簡単な実装）
                    return {
                        'package': package_name,
                        'version': '1.0.0',
                        'source': source,
                        'status': 'resolved'
                    }
                else:
                    return {
                        'package': package_name,
                        'version': '2.0.0',
                        'source': source,
                        'status': 'resolved'
                    }
            
            def resolve_with_fallback(self, package_name):
                last_error = None
                
                for source in self.fallback_sources:
                    try:
                        result = self.resolve_dependency(package_name, source)
                        self.resolved_packages.add(package_name)
                        return result
                    except (ConnectionError, TimeoutError) as e:
                        last_error = e
                        continue
                
                raise last_error or Exception(f"Failed to resolve {package_name}")
        
        # 依存関係回復テスト
        resolver = DependencyRecovery()
        
        # 正常パッケージの解決
        result = resolver.resolve_with_fallback('normal_package')
        assert result['status'] == 'resolved'
        assert result['source'] == 'primary_source'
        
        # 失敗パッケージの回復
        result = resolver.resolve_with_fallback('failing_package')
        assert result['status'] == 'resolved'
        assert result['source'] == 'local_cache'  # フォールバック先で成功

    @pytest.mark.integration
    def test_configuration_error_recovery(self):
        """設定エラーの回復シナリオテスト."""
        # 設定回復機能
        class ConfigurationRecovery:
            def __init__(self, config_paths):
                self.config_paths = config_paths
                self.default_config = {
                    'app_name': 'setup_repo',
                    'version': '1.0.0',
                    'debug': False,
                    'timeout': 30
                }
            
            def load_config_file(self, config_path):
                if not Path(config_path).exists():
                    raise FileNotFoundError(f"Config file not found: {config_path}")
                
                # 設定ファイルの内容をシミュレート
                if 'invalid' in str(config_path):
                    raise ValueError("Invalid JSON format")
                elif 'corrupt' in str(config_path):
                    raise OSError("File is corrupted")
                else:
                    return {
                        'app_name': 'setup_repo',
                        'version': '2.0.0',
                        'debug': True,
                        'timeout': 60,
                        'source': str(config_path)
                    }
            
            def load_with_fallback(self):
                config = self.default_config.copy()
                loaded_from = 'default'
                
                for config_path in self.config_paths:
                    try:
                        file_config = self.load_config_file(config_path)
                        config.update(file_config)
                        loaded_from = config_path
                        break
                    except (FileNotFoundError, ValueError, OSError):
                        continue
                
                config['loaded_from'] = loaded_from
                return config
        
        # テスト用設定ファイル作成
        valid_config = self.temp_dir / "valid_config.json"
        valid_config.write_text('{"app_name": "test_app"}')
        
        # 設定回復テスト
        config_paths = [
            self.temp_dir / "missing_config.json",
            self.temp_dir / "invalid_config.json",
            valid_config
        ]
        
        recovery = ConfigurationRecovery(config_paths)
        config = recovery.load_with_fallback()
        
        # 設定回復の検証
        assert config['app_name'] == 'setup_repo'  # ファイルから読み込み成功
        assert config['loaded_from'] == valid_config

    @pytest.mark.integration
    def test_process_failure_recovery(self):
        """プロセス失敗の回復シナリオテスト."""
        # プロセス回復機能
        class ProcessRecovery:
            def __init__(self, max_retries=3):
                self.max_retries = max_retries
                self.process_attempts = {}
            
            def execute_process(self, command, simulate_failure=False):
                process_id = f"proc_{len(self.process_attempts)}"
                self.process_attempts[process_id] = self.process_attempts.get(process_id, 0) + 1
                
                # 失敗シミュレーション
                if simulate_failure and self.process_attempts[process_id] <= 2:
                    if self.process_attempts[process_id] == 1:
                        raise OSError("Process crashed")
                    elif self.process_attempts[process_id] == 2:
                        raise TimeoutError("Process timeout")
                
                # 成功レスポンス
                return {
                    'returncode': 0,
                    'stdout': 'Process completed successfully',
                    'stderr': '',
                    'attempts': self.process_attempts[process_id]
                }
            
            def execute_with_retry(self, command):
                last_error = None
                
                for attempt in range(self.max_retries + 1):
                    try:
                        return self.execute_process(command, simulate_failure=True)
                    except (OSError, TimeoutError) as e:
                        last_error = e
                        if attempt < self.max_retries:
                            time.sleep(0.01)
                            continue
                        else:
                            raise last_error
                
                raise last_error
        
        # プロセス回復テスト
        process_manager = ProcessRecovery(max_retries=3)
        
        # 回復成功シナリオ
        result = process_manager.execute_with_retry("test_command")
        assert result['returncode'] == 0
        assert result['attempts'] == 3  # 2回失敗後、3回目で成功

    @pytest.mark.integration
    def test_resource_exhaustion_recovery(self):
        """リソース枯渇の回復シナリオテスト."""
        # リソース回復機能
        class ResourceRecovery:
            def __init__(self):
                self.memory_usage = 0
                self.max_memory = 1000  # MB
                self.cleanup_threshold = 800  # MB
            
            def allocate_resource(self, size, force_cleanup=False):
                if self.memory_usage + size > self.max_memory:
                    if not force_cleanup:
                        raise MemoryError("Insufficient memory")
                    else:
                        # 強制クリーンアップ
                        self.cleanup_resources()
                
                self.memory_usage += size
                return f"Allocated {size}MB, total: {self.memory_usage}MB"
            
            def cleanup_resources(self):
                # リソースクリーンアップシミュレーション
                cleaned_up = self.memory_usage * 0.7  # 70%をクリーンアップ
                self.memory_usage = int(self.memory_usage * 0.3)
                return f"Cleaned up {int(cleaned_up)}MB"
            
            def smart_allocate(self, size):
                try:
                    return self.allocate_resource(size)
                except MemoryError:
                    # 自動クリーンアップして再試行
                    cleanup_result = self.cleanup_resources()
                    try:
                        allocation_result = self.allocate_resource(size)
                        return f"After cleanup: {allocation_result}"
                    except MemoryError:
                        raise MemoryError("Insufficient memory even after cleanup")
        
        # リソース回復テスト
        resource_manager = ResourceRecovery()
        
        # 通常の割り当て
        result = resource_manager.smart_allocate(500)
        assert "Allocated 500MB" in result
        
        # リソース枯渇からの回復
        result = resource_manager.smart_allocate(600)  # 合計1100MB > 1000MB
        assert "After cleanup" in result

    @pytest.mark.integration
    @pytest.mark.skipif(platform.system() == "Windows", reason="Unix固有のエラー回復")
    def test_unix_specific_error_recovery(self):
        """Unix固有のエラー回復シナリオテスト."""
        # Unix固有の回復機能
        class UnixErrorRecovery:
            def __init__(self):
                self.signal_handlers = {}
            
            def handle_signal_error(self, signal_name):
                if signal_name == 'SIGTERM':
                    return {'action': 'graceful_shutdown', 'success': True}
                elif signal_name == 'SIGINT':
                    return {'action': 'interrupt_handling', 'success': True}
                elif signal_name == 'SIGUSR1':
                    return {'action': 'reload_config', 'success': True}
                else:
                    return {'action': 'unknown_signal', 'success': False}
            
            def recover_from_permission_error(self, file_path):
                # 権限エラーからの回復試行
                recovery_actions = [
                    'check_file_ownership',
                    'attempt_chmod',
                    'use_alternative_path'
                ]
                
                for action in recovery_actions:
                    if action == 'use_alternative_path':
                        # 代替パスの使用（常に成功）
                        return {
                            'action': action,
                            'success': True,
                            'alternative_path': f"/tmp/{Path(file_path).name}"
                        }
                
                return {'action': 'recovery_failed', 'success': False}
        
        # Unix固有回復テスト
        unix_recovery = UnixErrorRecovery()
        
        # シグナル処理回復
        result = unix_recovery.handle_signal_error('SIGTERM')
        assert result['success'] is True
        assert result['action'] == 'graceful_shutdown'
        
        # 権限エラー回復
        result = unix_recovery.recover_from_permission_error('/etc/restricted_file')
        assert result['success'] is True
        assert 'alternative_path' in result

    @pytest.mark.integration
    @pytest.mark.skipif(platform.system() != "Windows", reason="Windows固有のエラー回復")
    def test_windows_specific_error_recovery(self):
        """Windows固有のエラー回復シナリオテスト."""
        # Windows固有の回復機能
        class WindowsErrorRecovery:
            def __init__(self):
                self.error_codes = {
                    2: 'FILE_NOT_FOUND',
                    3: 'PATH_NOT_FOUND',
                    5: 'ACCESS_DENIED',
                    32: 'SHARING_VIOLATION'
                }
            
            def handle_windows_error(self, error_code):
                error_name = self.error_codes.get(error_code, 'UNKNOWN_ERROR')
                
                if error_code == 5:  # ACCESS_DENIED
                    return {
                        'action': 'request_elevation',
                        'success': True,
                        'message': 'Requesting administrator privileges'
                    }
                elif error_code == 32:  # SHARING_VIOLATION
                    return {
                        'action': 'retry_after_delay',
                        'success': True,
                        'message': 'File is in use, retrying after delay'
                    }
                elif error_code in [2, 3]:  # FILE/PATH_NOT_FOUND
                    return {
                        'action': 'create_missing_path',
                        'success': True,
                        'message': 'Creating missing directories'
                    }
                else:
                    return {
                        'action': 'unknown_error',
                        'success': False,
                        'message': f'Unknown error code: {error_code}'
                    }
            
            def recover_from_registry_error(self):
                # レジストリエラーからの回復
                return {
                    'action': 'use_file_config',
                    'success': True,
                    'message': 'Falling back to file-based configuration'
                }
        
        # Windows固有回復テスト
        windows_recovery = WindowsErrorRecovery()
        
        # アクセス拒否エラー回復
        result = windows_recovery.handle_windows_error(5)
        assert result['success'] is True
        assert result['action'] == 'request_elevation'
        
        # レジストリエラー回復
        result = windows_recovery.recover_from_registry_error()
        assert result['success'] is True
        assert result['action'] == 'use_file_config'

    @pytest.mark.integration
    def test_comprehensive_error_recovery_workflow(self):
        """包括的なエラー回復ワークフローテスト."""
        # 包括的回復システム
        class ComprehensiveRecovery:
            def __init__(self):
                self.recovery_log = []
                self.recovery_strategies = {
                    'file_error': self._recover_file_error,
                    'network_error': self._recover_network_error,
                    'process_error': self._recover_process_error,
                    'config_error': self._recover_config_error
                }
            
            def _recover_file_error(self, error_info):
                self.recovery_log.append(f"File error recovery: {error_info}")
                return {'success': True, 'method': 'file_fallback'}
            
            def _recover_network_error(self, error_info):
                self.recovery_log.append(f"Network error recovery: {error_info}")
                return {'success': True, 'method': 'network_retry'}
            
            def _recover_process_error(self, error_info):
                self.recovery_log.append(f"Process error recovery: {error_info}")
                return {'success': True, 'method': 'process_restart'}
            
            def _recover_config_error(self, error_info):
                self.recovery_log.append(f"Config error recovery: {error_info}")
                return {'success': True, 'method': 'default_config'}
            
            def execute_with_recovery(self, operation_type, operation_data):
                try:
                    # 操作の実行をシミュレート
                    if operation_type == 'risky_operation':
                        raise Exception(f"Simulated {operation_data} error")
                    
                    return {'success': True, 'result': 'Operation completed'}
                
                except Exception as e:
                    # エラータイプの判定と回復
                    error_type = self._classify_error(str(e))
                    if error_type in self.recovery_strategies:
                        recovery_result = self.recovery_strategies[error_type](str(e))
                        return {
                            'success': recovery_result['success'],
                            'recovered': True,
                            'recovery_method': recovery_result['method'],
                            'original_error': str(e)
                        }
                    else:
                        return {
                            'success': False,
                            'recovered': False,
                            'error': str(e)
                        }
            
            def _classify_error(self, error_message):
                if 'file' in error_message.lower():
                    return 'file_error'
                elif 'network' in error_message.lower():
                    return 'network_error'
                elif 'process' in error_message.lower():
                    return 'process_error'
                elif 'config' in error_message.lower():
                    return 'config_error'
                else:
                    return 'unknown_error'
        
        # 包括的回復テスト
        recovery_system = ComprehensiveRecovery()
        
        # 各種エラーの回復テスト
        test_cases = [
            ('risky_operation', 'file'),
            ('risky_operation', 'network'),
            ('risky_operation', 'process'),
            ('risky_operation', 'config')
        ]
        
        for operation_type, error_data in test_cases:
            result = recovery_system.execute_with_recovery(operation_type, error_data)
            assert result['recovered'] is True
            assert result['success'] is True
            assert 'recovery_method' in result
        
        # 回復ログの検証
        assert len(recovery_system.recovery_log) == 4
        assert all('recovery' in log for log in recovery_system.recovery_log)