"""品質エラー処理機能のテスト."""

import pytest
import platform
from pathlib import Path
from unittest.mock import Mock, patch, MagicMock
from ..multiplatform.helpers import verify_current_platform, skip_if_not_platform


class TestQualityErrorHandling:
    """品質エラー処理のテストクラス."""

    def setup_method(self):
        """テストメソッドの前処理."""
        self.platform_info = verify_current_platform()

    @pytest.mark.unit
    def test_lint_error_handling(self):
        """リンティングエラーの処理テスト."""
        # モックエラーレスポンス
        mock_error = {
            "file": "test.py",
            "line": 10,
            "column": 5,
            "message": "Line too long",
            "code": "E501"
        }
        
        # エラー処理ロジックのテスト
        assert mock_error["code"] == "E501"
        assert mock_error["line"] == 10

    @pytest.mark.unit
    def test_type_check_error_handling(self):
        """型チェックエラーの処理テスト."""
        mock_mypy_error = {
            "file": "test.py",
            "line": 15,
            "message": "Incompatible types",
            "severity": "error"
        }
        
        # MyPyエラー処理のテスト
        assert mock_mypy_error["severity"] == "error"
        assert "Incompatible types" in mock_mypy_error["message"]

    @pytest.mark.unit
    def test_test_failure_error_handling(self):
        """テスト失敗エラーの処理テスト."""
        mock_test_error = {
            "test": "test_example",
            "file": "test_example.py",
            "error": "AssertionError: Expected 5, got 3",
            "traceback": ["line1", "line2", "line3"]
        }
        
        # テストエラー処理のテスト
        assert "AssertionError" in mock_test_error["error"]
        assert len(mock_test_error["traceback"]) == 3

    @pytest.mark.unit
    def test_security_error_handling(self):
        """セキュリティエラーの処理テスト."""
        mock_security_error = {
            "file": "vulnerable.py",
            "line": 20,
            "issue": "Hardcoded password",
            "severity": "HIGH",
            "confidence": "HIGH"
        }
        
        # セキュリティエラー処理のテスト
        assert mock_security_error["severity"] == "HIGH"
        assert mock_security_error["confidence"] == "HIGH"

    @pytest.mark.unit
    def test_coverage_error_handling(self):
        """カバレッジエラーの処理テスト."""
        mock_coverage_error = {
            "file": "uncovered.py",
            "missing_lines": [10, 11, 12, 15],
            "coverage_percent": 75.5
        }
        
        # カバレッジエラー処理のテスト
        assert len(mock_coverage_error["missing_lines"]) == 4
        assert mock_coverage_error["coverage_percent"] < 80

    @pytest.mark.unit
    def test_dependency_error_handling(self):
        """依存関係エラーの処理テスト."""
        mock_dependency_error = {
            "package": "requests",
            "version": "2.25.0",
            "vulnerability": "CVE-2021-33503",
            "severity": "MEDIUM"
        }
        
        # 依存関係エラー処理のテスト
        assert mock_dependency_error["package"] == "requests"
        assert "CVE-" in mock_dependency_error["vulnerability"]

    @pytest.mark.unit
    @pytest.mark.skipif(platform.system() == "Windows", reason="Unix固有のエラー処理")
    def test_unix_specific_error_handling(self):
        """Unix固有のエラー処理テスト."""
        # Unix固有のエラー処理
        mock_unix_error = {
            "type": "PermissionError",
            "message": "Permission denied",
            "errno": 13
        }
        
        assert mock_unix_error["errno"] == 13
        assert mock_unix_error["type"] == "PermissionError"

    @pytest.mark.unit
    @pytest.mark.skipif(platform.system() != "Windows", reason="Windows固有のエラー処理")
    def test_windows_specific_error_handling(self):
        """Windows固有のエラー処理テスト."""
        # Windows固有のエラー処理
        mock_windows_error = {
            "type": "WindowsError",
            "message": "Access is denied",
            "winerror": 5
        }
        
        assert mock_windows_error["winerror"] == 5
        assert mock_windows_error["type"] == "WindowsError"

    @pytest.mark.unit
    def test_error_aggregation(self):
        """エラー集約処理のテスト."""
        errors = [
            {"type": "lint", "count": 5},
            {"type": "type", "count": 2},
            {"type": "test", "count": 1},
            {"type": "security", "count": 0}
        ]
        
        # エラー集約のテスト
        total_errors = sum(error["count"] for error in errors)
        assert total_errors == 8
        
        # 重要度別分類
        critical_errors = [e for e in errors if e["type"] in ["security", "test"]]
        assert len(critical_errors) == 2

    @pytest.mark.unit
    def test_error_reporting_format(self):
        """エラーレポート形式のテスト."""
        error_report = {
            "timestamp": "2024-12-01T10:00:00Z",
            "platform": self.platform_info["system"],
            "python_version": self.platform_info["python_version"],
            "errors": {
                "lint": 3,
                "type": 1,
                "test": 0,
                "security": 2
            },
            "total": 6
        }
        
        # レポート形式のテスト
        assert error_report["total"] == 6
        assert error_report["platform"] in ["Windows", "Linux", "Darwin"]
        assert "timestamp" in error_report

    @pytest.mark.unit
    def test_error_threshold_checking(self):
        """エラー閾値チェックのテスト."""
        thresholds = {
            "lint": 10,
            "type": 5,
            "test": 0,
            "security": 0
        }
        
        current_errors = {
            "lint": 8,
            "type": 3,
            "test": 0,
            "security": 1
        }
        
        # 閾値チェック
        violations = []
        for error_type, count in current_errors.items():
            if count > thresholds[error_type]:
                violations.append(error_type)
        
        assert "security" in violations
        assert "lint" not in violations
        assert len(violations) == 1