"""CIエラーハンドリング機能のテスト."""

import pytest
import platform
from unittest.mock import Mock, patch
from ..multiplatform.helpers import verify_current_platform


class TestCIErrorHandler:
    """CIエラーハンドリングのテストクラス."""

    def setup_method(self):
        """テストメソッドの前処理."""
        self.platform_info = verify_current_platform()

    @pytest.mark.unit
    def test_build_failure_handling(self):
        """ビルド失敗ハンドリングのテスト."""
        # ビルドエラー情報
        build_error = {
            'type': 'build_failure',
            'exit_code': 1,
            'command': 'python setup.py build',
            'stdout': 'Building...',
            'stderr': 'Error: Missing dependency',
            'duration': 45.2
        }
        
        # エラーハンドリング関数
        def handle_build_error(error_info):
            if error_info['exit_code'] != 0:
                return {
                    'status': 'failed',
                    'reason': 'build_error',
                    'message': f"Build failed with exit code {error_info['exit_code']}",
                    'suggestion': 'Check dependencies and build configuration',
                    'retry_recommended': True
                }
            return {'status': 'success'}
        
        # ビルドエラーハンドリングテスト
        result = handle_build_error(build_error)
        assert result['status'] == 'failed'
        assert result['reason'] == 'build_error'
        assert result['retry_recommended'] is True

    @pytest.mark.unit
    def test_test_failure_handling(self):
        """テスト失敗ハンドリングのテスト."""
        # テストエラー情報
        test_error = {
            'type': 'test_failure',
            'failed_tests': [
                {'name': 'test_example', 'error': 'AssertionError: Expected 5, got 3'},
                {'name': 'test_integration', 'error': 'ConnectionError: Unable to connect'}
            ],
            'total_tests': 50,
            'passed_tests': 48,
            'failed_tests_count': 2
        }
        
        # テストエラーハンドリング関数
        def handle_test_error(error_info):
            failed_count = error_info['failed_tests_count']
            total_count = error_info['total_tests']
            failure_rate = failed_count / total_count
            
            if failure_rate > 0.1:  # 10%以上の失敗率
                severity = 'high'
                retry_recommended = False
            elif failure_rate > 0.05:  # 5%以上の失敗率
                severity = 'medium'
                retry_recommended = True
            else:
                severity = 'low'
                retry_recommended = True
            
            return {
                'status': 'failed',
                'severity': severity,
                'failure_rate': failure_rate,
                'failed_count': failed_count,
                'retry_recommended': retry_recommended,
                'message': f"{failed_count} out of {total_count} tests failed"
            }
        
        # テストエラーハンドリングテスト
        result = handle_test_error(test_error)
        assert result['status'] == 'failed'
        assert result['severity'] == 'low'  # 2/50 = 4% < 5%
        assert result['retry_recommended'] is True

    @pytest.mark.unit
    def test_dependency_error_handling(self):
        """依存関係エラーハンドリングのテスト."""
        # 依存関係エラー情報
        dependency_error = {
            'type': 'dependency_error',
            'missing_packages': ['requests', 'numpy'],
            'version_conflicts': [
                {'package': 'flask', 'required': '>=2.0.0', 'installed': '1.1.4'}
            ],
            'platform': self.platform_info['system']
        }
        
        # 依存関係エラーハンドリング関数
        def handle_dependency_error(error_info):
            missing = error_info.get('missing_packages', [])
            conflicts = error_info.get('version_conflicts', [])
            
            suggestions = []
            if missing:
                suggestions.append(f"Install missing packages: {', '.join(missing)}")
            if conflicts:
                for conflict in conflicts:
                    suggestions.append(f"Update {conflict['package']} to {conflict['required']}")
            
            return {
                'status': 'failed',
                'reason': 'dependency_error',
                'missing_count': len(missing),
                'conflict_count': len(conflicts),
                'suggestions': suggestions,
                'retry_recommended': True,
                'fix_command': 'pip install -r requirements.txt --upgrade'
            }
        
        # 依存関係エラーハンドリングテスト
        result = handle_dependency_error(dependency_error)
        assert result['status'] == 'failed'
        assert result['missing_count'] == 2
        assert result['conflict_count'] == 1
        assert len(result['suggestions']) == 3

    @pytest.mark.unit
    def test_timeout_error_handling(self):
        """タイムアウトエラーハンドリングのテスト."""
        # タイムアウトエラー情報
        timeout_error = {
            'type': 'timeout_error',
            'operation': 'test_execution',
            'timeout_limit': 300,  # 5分
            'actual_duration': 350,  # 5分50秒
            'stage': 'integration_tests'
        }
        
        # タイムアウトエラーハンドリング関数
        def handle_timeout_error(error_info):
            operation = error_info['operation']
            limit = error_info['timeout_limit']
            actual = error_info['actual_duration']
            
            return {
                'status': 'failed',
                'reason': 'timeout',
                'operation': operation,
                'timeout_limit': limit,
                'actual_duration': actual,
                'exceeded_by': actual - limit,
                'suggestion': f'Consider increasing timeout limit or optimizing {operation}',
                'retry_recommended': True,
                'recommended_timeout': limit * 1.5  # 50%増加
            }
        
        # タイムアウトエラーハンドリングテスト
        result = handle_timeout_error(timeout_error)
        assert result['status'] == 'failed'
        assert result['reason'] == 'timeout'
        assert result['exceeded_by'] == 50
        assert result['recommended_timeout'] == 450

    @pytest.mark.unit
    def test_resource_exhaustion_handling(self):
        """リソース枯渇エラーハンドリングのテスト."""
        # リソース枯渇エラー情報
        resource_error = {
            'type': 'resource_exhaustion',
            'resource_type': 'memory',
            'limit': '7GB',
            'usage': '6.8GB',
            'available': '0.2GB',
            'process': 'pytest'
        }
        
        # リソース枯渇エラーハンドリング関数
        def handle_resource_error(error_info):
            resource_type = error_info['resource_type']
            usage_percent = 97.1  # 6.8/7 * 100
            
            if usage_percent > 95:
                severity = 'critical'
                retry_recommended = False
            elif usage_percent > 85:
                severity = 'high'
                retry_recommended = True
            else:
                severity = 'medium'
                retry_recommended = True
            
            suggestions = []
            if resource_type == 'memory':
                suggestions.extend([
                    'Reduce test parallelism',
                    'Use memory profiling to identify leaks',
                    'Consider running tests in smaller batches'
                ])
            elif resource_type == 'disk':
                suggestions.extend([
                    'Clean up temporary files',
                    'Use smaller test datasets',
                    'Enable disk cleanup in CI'
                ])
            
            return {
                'status': 'failed',
                'reason': 'resource_exhaustion',
                'resource_type': resource_type,
                'severity': severity,
                'usage_percent': usage_percent,
                'suggestions': suggestions,
                'retry_recommended': retry_recommended
            }
        
        # リソース枯渇エラーハンドリングテスト
        result = handle_resource_error(resource_error)
        assert result['status'] == 'failed'
        assert result['severity'] == 'critical'
        assert result['retry_recommended'] is False
        assert len(result['suggestions']) == 3

    @pytest.mark.unit
    def test_network_error_handling(self):
        """ネットワークエラーハンドリングのテスト."""
        # ネットワークエラー情報
        network_error = {
            'type': 'network_error',
            'operation': 'package_download',
            'url': 'https://pypi.org/simple/requests/',
            'error_code': 'ConnectionTimeout',
            'retry_count': 2,
            'max_retries': 3
        }
        
        # ネットワークエラーハンドリング関数
        def handle_network_error(error_info):
            retry_count = error_info['retry_count']
            max_retries = error_info['max_retries']
            
            if retry_count >= max_retries:
                return {
                    'status': 'failed',
                    'reason': 'network_error',
                    'final_attempt': True,
                    'retry_recommended': False,
                    'suggestion': 'Check network connectivity and try again later'
                }
            else:
                return {
                    'status': 'retry',
                    'reason': 'network_error',
                    'retry_count': retry_count + 1,
                    'retry_recommended': True,
                    'wait_time': min(2 ** retry_count, 60)  # Exponential backoff
                }
        
        # ネットワークエラーハンドリングテスト
        result = handle_network_error(network_error)
        assert result['status'] == 'retry'
        assert result['retry_count'] == 3
        assert result['wait_time'] == 4  # 2^2

    @pytest.mark.unit
    def test_permission_error_handling(self):
        """権限エラーハンドリングのテスト."""
        # 権限エラー情報
        permission_error = {
            'type': 'permission_error',
            'operation': 'file_write',
            'path': '/etc/config.conf',
            'user': 'runner',
            'required_permission': 'write',
            'platform': self.platform_info['system']
        }
        
        # 権限エラーハンドリング関数
        def handle_permission_error(error_info):
            platform = error_info['platform']
            operation = error_info['operation']
            path = error_info['path']
            
            suggestions = []
            if platform == 'Linux' or platform == 'Darwin':
                suggestions.extend([
                    f'Check file permissions: ls -la {path}',
                    f'Change permissions: chmod 644 {path}',
                    'Run with appropriate user privileges'
                ])
            elif platform == 'Windows':
                suggestions.extend([
                    'Check file properties and security settings',
                    'Run as administrator if required',
                    'Verify user has write access to the directory'
                ])
            
            return {
                'status': 'failed',
                'reason': 'permission_error',
                'operation': operation,
                'path': path,
                'platform': platform,
                'suggestions': suggestions,
                'retry_recommended': False,
                'requires_manual_fix': True
            }
        
        # 権限エラーハンドリングテスト
        result = handle_permission_error(permission_error)
        assert result['status'] == 'failed'
        assert result['reason'] == 'permission_error'
        assert result['requires_manual_fix'] is True
        assert len(result['suggestions']) >= 3

    @pytest.mark.unit
    @pytest.mark.skipif(platform.system() == "Windows", reason="Unix固有のエラーハンドリング")
    def test_unix_specific_error_handling(self):
        """Unix固有のエラーハンドリングテスト."""
        # Unix固有のエラー情報
        unix_error = {
            'type': 'signal_error',
            'signal': 'SIGKILL',
            'signal_number': 9,
            'process': 'test_runner',
            'pid': 12345
        }
        
        # Unix固有エラーハンドリング関数
        def handle_unix_signal_error(error_info):
            signal_name = error_info['signal']
            signal_num = error_info['signal_number']
            
            signal_meanings = {
                'SIGKILL': 'Process was forcibly terminated',
                'SIGTERM': 'Process received termination request',
                'SIGINT': 'Process was interrupted',
                'SIGSEGV': 'Segmentation fault occurred'
            }
            
            return {
                'status': 'failed',
                'reason': 'signal_error',
                'signal': signal_name,
                'meaning': signal_meanings.get(signal_name, 'Unknown signal'),
                'retry_recommended': signal_name not in ['SIGKILL', 'SIGSEGV'],
                'investigation_needed': signal_name in ['SIGSEGV', 'SIGABRT']
            }
        
        # Unix固有エラーハンドリングテスト
        result = handle_unix_signal_error(unix_error)
        assert result['status'] == 'failed'
        assert result['signal'] == 'SIGKILL'
        assert result['retry_recommended'] is False

    @pytest.mark.unit
    @pytest.mark.skipif(platform.system() != "Windows", reason="Windows固有のエラーハンドリング")
    def test_windows_specific_error_handling(self):
        """Windows固有のエラーハンドリングテスト."""
        # Windows固有のエラー情報
        windows_error = {
            'type': 'windows_error',
            'error_code': 5,  # Access Denied
            'error_message': 'Access is denied',
            'operation': 'file_access',
            'path': 'C:\\Windows\\System32\\config'
        }
        
        # Windows固有エラーハンドリング関数
        def handle_windows_error(error_info):
            error_code = error_info['error_code']
            
            error_meanings = {
                2: 'File not found',
                3: 'Path not found',
                5: 'Access denied',
                32: 'File is in use by another process',
                183: 'File already exists'
            }
            
            return {
                'status': 'failed',
                'reason': 'windows_error',
                'error_code': error_code,
                'meaning': error_meanings.get(error_code, 'Unknown Windows error'),
                'retry_recommended': error_code not in [5, 2, 3],
                'requires_admin': error_code == 5
            }
        
        # Windows固有エラーハンドリングテスト
        result = handle_windows_error(windows_error)
        assert result['status'] == 'failed'
        assert result['error_code'] == 5
        assert result['requires_admin'] is True

    @pytest.mark.unit
    def test_error_aggregation_and_reporting(self):
        """エラー集約とレポート生成のテスト."""
        # 複数のエラー情報
        errors = [
            {'type': 'build_failure', 'severity': 'high', 'count': 1},
            {'type': 'test_failure', 'severity': 'medium', 'count': 3},
            {'type': 'lint_error', 'severity': 'low', 'count': 15},
            {'type': 'dependency_error', 'severity': 'high', 'count': 2}
        ]
        
        # エラー集約関数
        def aggregate_errors(error_list):
            total_errors = sum(error['count'] for error in error_list)
            severity_counts = {'high': 0, 'medium': 0, 'low': 0}
            
            for error in error_list:
                severity_counts[error['severity']] += error['count']
            
            # 全体的な重要度の決定
            if severity_counts['high'] > 0:
                overall_severity = 'high'
            elif severity_counts['medium'] > 0:
                overall_severity = 'medium'
            else:
                overall_severity = 'low'
            
            return {
                'total_errors': total_errors,
                'severity_breakdown': severity_counts,
                'overall_severity': overall_severity,
                'critical_errors': severity_counts['high'],
                'requires_immediate_attention': severity_counts['high'] > 0
            }
        
        # エラー集約テスト
        result = aggregate_errors(errors)
        assert result['total_errors'] == 21
        assert result['overall_severity'] == 'high'
        assert result['critical_errors'] == 3
        assert result['requires_immediate_attention'] is True

    @pytest.mark.unit
    def test_error_recovery_strategies(self):
        """エラー回復戦略のテスト."""
        # エラー回復戦略関数
        def get_recovery_strategy(error_type, error_context):
            strategies = {
                'build_failure': {
                    'immediate': ['clean_build', 'retry_build'],
                    'investigation': ['check_dependencies', 'review_build_logs'],
                    'prevention': ['update_dependencies', 'improve_build_scripts']
                },
                'test_failure': {
                    'immediate': ['rerun_failed_tests', 'check_test_environment'],
                    'investigation': ['analyze_test_logs', 'review_test_data'],
                    'prevention': ['improve_test_stability', 'add_test_retries']
                },
                'network_error': {
                    'immediate': ['retry_with_backoff', 'check_connectivity'],
                    'investigation': ['verify_endpoints', 'check_firewall'],
                    'prevention': ['add_offline_mode', 'cache_dependencies']
                }
            }
            
            return strategies.get(error_type, {
                'immediate': ['manual_investigation'],
                'investigation': ['review_logs'],
                'prevention': ['improve_error_handling']
            })
        
        # エラー回復戦略テスト
        build_strategy = get_recovery_strategy('build_failure', {})
        assert 'clean_build' in build_strategy['immediate']
        assert 'check_dependencies' in build_strategy['investigation']
        
        network_strategy = get_recovery_strategy('network_error', {})
        assert 'retry_with_backoff' in network_strategy['immediate']
        assert 'add_offline_mode' in network_strategy['prevention']